Workbook
Name CountryRiskParamsRange: #REF!
Name GE: FieldValidation!$E$60
Name ICO: FieldValidation!$E$84
Name KPS: FieldValidation!$E$61
Name LEGALL: FieldValidation!$E$19:$E$30
Name LEGGE: FieldValidation!$E$32
Name LEGTRUST: FieldValidation!$E$31
Name MCNO: FieldValidation!$E$83
Name MSBMST: FieldValidation!$E$71:$E$82
Name OC: FieldValidation!$E$38:$E$57
Name PIF: FieldValidation!$E$62:$E$65
Name PIV: FieldValidation!$E$58
Name PSP: FieldValidation!$E$34:$E$37
Name PTC: FieldValidation!$E$69
Name PTF: FieldValidation!$E$59
Name RE: FieldValidation!$E$66:$E$68
Name RiskCompanyValueRange: #REF!
Name RiskIntAccUsageRange: #REF!
Name RiskParamsRange: #REF!
Name TEONP: FieldValidation!$E$70
Name TRUST: FieldValidation!$E$85

Sheet Introduction
A2: Corporate Account Opening Questionnaire Introduction
B4: Thank you for joining Bitstamp! We are obliged to ask you to fill in this questionnaire in order to comply with our regulatory requirements.
B6: Field background indicating an obligatory field yet to be filled-in.
B7: Field background indicating an optional field or a field depending on other choices (background will be dynamically changed to light red if obligatory).
B8: Field background indicating a required data field.
B10: Please ensure to return a questionnaire without light-red background fields (on AML Policy sheet only if applicable).
C12: Sincerely, the Bitstamp Team
A15: Sheet 2 | B15: Company Information and Intended Activity | C15: Please provide basic company information along with information regarding intended activity, volumes and frequencies of transactions.
A16: Sheet 3 | B16: Ownership, Source of Funds | C16: Background infromation on ownership or trustee(s) and settler(s).
A17: Sheet 4 | B17: Representatives and Acc. Users | C17: Information on individuals that are authorized to act on the account (control persons and/or account users).
A18: Sheet 4 | B18: Bank Accounts | C18: Information on individuals that are authorized to act on the account (control persons and/or account users).
A19: Sheet 6 | B19: Sanctions and AML Information | C19: Information on sanctioned industries, countries and historical AML information.

Sheet Company Info, Intended Activity
A2: Corporate Account Opening Questionnaire - Company Information and Intended Activity Required documents guidance based on selected Legal Entity Type, Account Type and Business Model - see below | E2: =CONCATENATE("Questionnaire version: ", G2) -> Questionnaire version: INC00005 | G2: INC00005 | I2: Document Version
A4: Section | B4: Question/Request | C4: Answer | E4: Comment/Instructions | G4: FieldCode | H4: Value Code | I4: Comment for development
A5: Contact person and date | B5: Full name | E5: This section is reserved for the individual that opening the account on behalf of the company. | G5: ContactPersonFullName | I5: text box/mandatory
B6: Title / Function | G6: ContactPersonTitle | I6: text box/mandatory
B7: E-mail | G7: ContactPersonEmail | I7: text box/mandatory
B8: Phone | E8: Current date and system format: | G8: ContactPersonPhone | I8: not mandatory field/text box
B9: Questionnaire valid at date (date of submission) | E9: =TODAY() -> 45090 | G9: QuestValidityDate | I9: field formated for dates/mandatory
A11: Company information | B11: Full company legal name (along with original legal type denomination) | E11: ='Entity and Documents Def'!F7 | G11: CompanyLegalName | I11: text box/mandatory
B12: Doing business as (other business names used if any, otherwise enter N/A) | G12: CompanyBusinessName | I12: not mandatory field/text box
B13: Registration/incorporation number | G13: CompanyRegisterNumber | I13: text box/mandatory
B14: Date of incorporation | G14: CompanyDateOfInc | I14: field formated for dates/mandatory
B15: Tax ID number (if applicable, otherwise enter N/A) | G15: CompanyTaxID | I15: text box
B16: Registered address | G16: CompanyRegisterAddress | I16: text box
B17: Country of incorporation | G17: CompanyCountryOfInc | I17: dropdown/mandatory
B18: State of incorporation (US only) | G18: CompanyStateOfInc | I18: dropdown/mandatory
B19: Office address | G19: CompanyOfficeAddress | I19: text box
B20: Principal place of business - Country | G20: CompanyPrincPlaceOfBus | I20: dropdown/mandatory
B21: Principal place of business - State (US only) | G21: CompanyPrincPlaceState | I21: dropdown/mandatory
B22: LEGAL ENTITY TYPE (Please check the row 54 for required documentation based on the selected legal type, entity and account type) | G22: CompanyLegalType | H22: =VLOOKUP(C22,FieldValidation!E12:I17,4,FALSE) -> #N/A | I22: dropdown/mandatory
B23: Company website (if applicable, otherwise enter N/A) | G23: CompanyWebiste | I23: text box
A25: Account Type and Business Model Information | B25: ACCOUNT TYPE (Please check the row 54 for required documentation based on the selected legal type, entity and account type) | E25: =IF(OR(ISBLANK(C22),ISBLANK(C25),ISBLANK(C26)),'Entity and Documents Def'!H8,"") -> Please select Legal Form, Account Type and Business Model! | G25: CompanyAccountType | H25: =VLOOKUP(C25,FieldValidation!E19:I32,4,FALSE) -> #N/A | I25: dropdown
B26: BUSINESS MODEL (Drop down depends on the selected Account type) | E26: ='Entity and Documents Def'!F5 | G26: CompanyBusinessModel | I26: dropdown/mandatory
B27: Provide a description of services that are offered | G27: CompanyServiceDescription | I27: text box
B28: Additional information (not mandatory) | G28: CompanyServiceAddInfo | I28: text box
A30: Regulatory approvals and licenses | B30: Name of supervisory authority (if applicable, otherwise enter N/A) | E30: Fill in if applicable. If not, enter N/A. | G30: CompanySupervAuth | I30: text box
B31: Link to the public database (if applicable, otherwise enter N/A) | E31: Provide a link with the details of the financial services license your company holds. If none, enter N/A. | G31: CompanyLinkToPublicDB | I31: text box
B32: Additional information (not mandatory) | E32: Please use in case you would like to provide additional information related to this section and if you select 'Other' and/or 'No' in any dropdown options in the section. | G32: CompanyRegulatoryAddInfo | I32: text box
A34: Intended account activity, volumes and frequencies | B34: What is the source of the funds that you will deposit to your Bitstamp account? | E34: If 'Customer funds' or 'Both' please fill in the AML Policy sheet or provide a signed Wolfsberg questionnaire. | G34: CompanySourceOfFunds | I34: dropdown/mandatory
B35: Do you intend to act on behalf of others? | E35: Select 'Yes' if you have underlying customers and will execute orders on behalf of them. | G35: IntendedOnBehalfOfOth | I35: dropdown/mandatory
B36: Intended account purpose (primary) | E36: Select the one that best fits your intended activities. If 'Other', please explain below. | G36: IntendedAccPurposePrimary | I36: dropdown/mandatory
B37: Intended account purpose (secondary - optional) | E37: Select only if there is a clearly envisioned secondary purpose, otherwise leave blank. | G37: IntendedAccPurposeSecondary | I37: dropdown/mandatory
B38: Intended account purpose (tertiary - optional) | E38: Select only if there is a clearly envisioned tertiary purpose, otherwise leave blank. | G38: IntendedAccPurposeTertiary | I38: dropdown/mandatory
B39: Describe account purpose and intended flow of funds through Bitstamp account. | E39: Provide description of how the account will be used along with intended flows of funds. | G39: IntendedAccPurpDesc | I39: text box
B40: Estimated amount deposited per year in fiat currencies (USD, EUR, GBP) | E40: Estimate how much fiat you intend to deposit to the Bitstamp account in a year (USD equivalent value). | G40: EstAmtDepositPerYearFiat | I40: dropdown/mandatory
B41: Estimated amount deposited per year in crypto | E41: Estimate how much crypto you intend to deposit to the Bitstamp account in a year (USD equivalent value). | G41: EstAmtDepositPerYearCrypto | I41: dropdown/mandatory
B42: Estimated number of deposits per year in fiat curr. (USD, EUR, GBP) - deposit frequency | E42: Estimate how many times you intend to make a fiat deposit in a year. | G42: EstNumDepositPerYearFiat | I42: dropdown/mandatory
B43: Estimated number of deposits per year in crypto - deposit frequency | E43: Estimate how many times you intend to make a crypto deposit in a year. | G43: EstNumDepositPerYearCrypto | I43: dropdown/mandatory
B44: Estimated amount withdrawn per year in fiat currencies (USD, EUR, GBP) | E44: Estimate how much fiat you intend to withdraw from the Bitstamp account in a year (USD equiv. value). | G44: EstAmtWithdrPerYearFiat | I44: dropdown/mandatory
B45: Estimated amount withdrawn per year in crypto | E45: Estimate how much crypto you intend to withdraw from the Bitstamp account in a year (USD equiv. value). | G45: EstAmtWithdrPerYearCrypto | I45: dropdown/mandatory
B46: Est. number of withdrawals per year in fiat curr. (USD, EUR, GBP) - withdr. frequency | E46: Estimate how many times you intend to make a fiat withdrawal in a year. | G46: EstNumWithdrPerYearFiat | I46: dropdown/mandatory
...

Sheet Ownership, SOF
A2: =VLOOKUP('Entity and Documents Def'!D8,'Entity and Documents Def'!A23:I42,5,FALSE) -> #N/A
B4: =('Entity and Documents Def'!D4)
B6: =CONCATENATE('Entity and Documents Def'!H3,VLOOKUP('Entity and Documents Def'!D7,'Entity and Documents Def'!A12:I18,6,FALSE),'Entity and Documents Def'!F3,VLOOKUP('Entity and Documents Def'!D8,'Entity and Documents Def'!A23:I42,6,FALSE)) -> #N/A | P6: Birthday Validation | Q6: =TODAY()-120*365 -> 1290 | R6: =TODAY() -> 45090
B7: INDIVIDUALS
B8: Stake | C8: Name | D8: Surname | E8: Date of Birth | F8: Nationality | G8: Address | H8: Post Code | I8: City | J8: Country of Residence | K8: State of Residence (US only) | L8: Social Security Number (if applicable) | M8: Actively Involved in the Company (Y/N)
A9: 1
A10: 2
A11: 3
A12: 4
A13: 5
A14: 6
A15: 7
A16: 8
A17: 9
A18: 10

Sheet Representatives and Acc. Users
A2: =VLOOKUP('Entity and Documents Def'!D8,'Entity and Documents Def'!A23:I42,7,FALSE) -> #N/A
B4: =('Entity and Documents Def'!D4) | P4: Birthday Validation | Q4: =TODAY()-120*365 -> 1290 | R4: =TODAY() -> 45090
P5: FieldCode
B6: =CONCATENATE('Entity and Documents Def'!H3,VLOOKUP('Entity and Documents Def'!D7,'Entity and Documents Def'!A12:I18,8,FALSE),'Entity and Documents Def'!F3,VLOOKUP('Entity and Documents Def'!D8,'Entity and Documents Def'!A23:I42,8,FALSE)) -> #N/A | P6: RepresentativesNoUBOs25
B7: Biststamp Account User Roles Explanation: | C7: 1. Account manager: can do everything – has access to all the settings and full access to all account features. 2. Administrator: has access management of subaccount (create and deactivate), can view account balance(s). 3. API Administrator: has access for creation and management of API keys, can view account balance(s). 4. Cash Manager: has access to the transfer of funds between subaccounts, can view account balance(s), can view and export transaction history and open orders, can view order history, can do withdrawals and deposits (FIAT and crypto), can confirm withdrawal requests through the mobile app, can stake (use earn feature). 5. Trader: has access to transfer of funds between subaccounts, can view account balance(s), can view and export of transaction history and open orders, can see order history, has full trading access (open and cancel orders), can do OTC trades, can stake (use earn feature), CAN'T do withdrawals or deposits. 6. Read only: can view account balance(s), can view and export transaction history and open orders, can view deposits.
B8: Bitstamp Account User (if applicable, see above) | C8: Role / Title in the Legal Entity | D8: Name | E8: Surname | F8: Date of Birth | G8: Nationality | H8: Address | I8: Post Code | J8: City | K8: Country of Residence | L8: State of Residence (US only) | M8: Social Security Number (if applicable)
A9: 1
A10: 2
A11: 3
A12: 4
A13: 5
A14: 6
A15: 7
A16: 8
A17: 9
A18: 10

Sheet Bank Accounts
A2: Corporate Account Opening Questionnaire Company Bank Accounts Intended to Deposit and Withdraw Fiat Funds
A4: Please provide information regarding bank accounts or payment services institutions that the company intends to use to deposit and withdraw fiat funds (USD, EUR, GBP) to and from the Bitstamp account. If the bank accounts are not yet open, please provide account type, name of the institution and account location. If you would like to explain anything regarding your bank or payment service providers (PSP*) you can enter that information in the comment section below. *PSP offer online services for accepting electronic payments by a variety of payment methods including credit card, bank-based payments such as direct debit, bank transfer, and real-time bank transfer based on online banking.
B6: Account Type | C6: Bank or Payment Services Provider (Name) | D6: Account Number or IBAN | E6: Account location (Country) | F6: SWIFT / BIC / ROUTING NUMBER / SORT CODE
A7: 1
A8: 2
A9: 3
A10: 4
A11: 5
A12: 6
A13: 7
A14: 8
A15: 9
A16: 10
A17: 11
A18: 12
... A36: 30
B38: Comment (not mandatory)
B45: BankAccountsAccType | C45: BankAccountsBankOrServiceName | D45: BankAccountsAccNumber | E45: BankAccountsAccLocation | F45: BankAccountsSWIFTBICRouting

Sheet Country List
A1: Code | B1: Country List (Verification)
A2: AF | B2: Afghanistan
A3: AX | B3: Aland
A4: AL | B4: Albania
A5: DZ | B5: Algeria
A6: AS | B6: American Samoa
A7: AD | B7: Andorra
A8: AO | B8: Angola
A9: AI | B9: Anguilla
A10: AG | B10: Antigua & Barbuda
A11: AR | B11: Argentina
A12: AM | B12: Armenia
... A249: ZW | B249: Zimbabwe

Sheet US State List
A1: Code | B1: US State List (Verification)
A2: N/A | B2: N/A
A3: AL | B3: Alabama
A4: AK | B4: Alaska
A5: AZ | B5: Arizona
A6: AR | B6: Arkansas
A7: CA | B7: California
A8: CO | B8: Colorado
A9: CT | B9: Connecticut
A10: DE | B10: Delaware
A11: DC | B11: District of Columbia
A12: FL | B12: Florida
... A53: WY | B53: Wyoming

Sheet Nationality List
B1: Nationality - Country | C1: Adjective
B2: Afghanistan | C2: Afgan
B3: Albania | C3: Albanian
B4: Algeria | C4: Algerian
B5: Andorra | C5: Andorran
B6: Angola | C6: Angolan
B7: Antigua and Barbuda | C7: Antugua and Barbudan
B8: Argentina | C8: Argenitine
B9: Armenia | C9: Armenian
B10: Australia | C10: Australian
B11: Austria | C11: Austrian
B12: Azerbaijan | C12: Azerbaijani
... B198: Zimbabwe | C198: Zimbabwean

Sheet FieldValidation
A1: Worksheet | B1: FieldCode | C1: FieldName | D1: Hierarchy | E1: ValueList | G1: Value - Upper Limit | I1: Required Documents Guidance Class | J1: Linked To Account Type
A5: General | E5: Yes
A6: General | E6: No
A7: General | E7: N/A
A9: Questionnaire | B9: ='Company Info, Intended Activity'!G9 -> QuestValidityDate | C9: ='Company Info, Intended Activity'!B9 -> Questionnaire valid at date (date of submission) | E9: =TODAY()-93 -> 44997 | G9: =TODAY()+92 -> 45182
A10: Questionnaire | B10: ='Company Info, Intended Activity'!G14 -> CompanyDateOfInc | C10: ='Company Info, Intended Activity'!B14 -> Date of incorporation | E10: 1 | G10: =TODAY() -> 45090
A11: Questionnaire
A12: Questionnaire | B12: ='Company Info, Intended Activity'!G22 -> CompanyLegalType | C12: ='Company Info, Intended Activity'!B22 -> LEGAL ENTITY TYPE (Please check the row 54 for required documentation based on the selected legal type, entity and account type) | E12: LLC | I12: LEGALL
A13: Questionnaire | B13: =B12 -> CompanyLegalType | C13: =C12 -> LEGAL ENTITY TYPE (Please check the row 54 for required documentation based on the selected legal type, entity and account type) | E13: S Corporation | I13: LEGALL
A14: Questionnaire | B14: =B13 -> CompanyLegalType | C14: =C13 -> LEGAL ENTITY TYPE (Please check the row 54 for required documentation based on the selected legal type, entity and account type) | E14: Limited Partnership | I14: LEGALL
A15: Questionnaire | B15: =B14 -> CompanyLegalType | C15: =C14 -> LEGAL ENTITY TYPE (Please check the row 54 for required documentation based on the selected legal type, entity and account type) | E15: Trust | I15: LEGTRUST
A16: Questionnaire | B16: =B14 -> CompanyLegalType | C16: =C14 -> LEGAL ENTITY TYPE (Please check the row 54 for required documentation based on the selected legal type, entity and account type) | E16: Government Entity | I16: LEGGE
A17: Questionnaire | B17: =B15 -> CompanyLegalType | C17: =C15 -> LEGAL ENTITY TYPE (Please check the row 54 for required documentation based on the selected legal type, entity and account type) | E17: Other | I17: LEGALL
A18: Questionnaire
A19: Questionnaire | B19: ='Company Info, Intended Activity'!G25 -> CompanyAccountType | C19: ='Company Info, Intended Activity'!B25 -> ACCOUNT TYPE (Please check the row 54 for required documentation based on the selected legal type, entity and account type) | E19: Professional Services Provider (e.g., Legal services, Accounting, etc…) | I19: PSP
A20: Questionnaire | B20: =B19 -> CompanyAccountType | C20: =C19 -> ACCOUNT TYPE (Please check the row 54 for required documentation based on the selected legal type, entity and account type) | E20: Other non-financial company | I20: OC
A21: Questionnaire | B21: =B20 -> CompanyAccountType | C21: =C20 -> ACCOUNT TYPE (Please check the row 54 for required documentation based on the selected legal type, entity and account type) | E21: Personal Investment Vehicle | I21: PIV
A22: Questionnaire | B22: =B21 -> CompanyAccountType | C22: =C21 -> ACCOUNT TYPE (Please check the row 54 for required documentation based on the selected legal type, entity and account type) | E22: Proprietary Trading Firm | I22: PTF
A23: Questionnaire | B23: =B22 -> CompanyAccountType | C23: =C22 -> ACCOUNT TYPE (Please check the row 54 for required documentation based on the selected legal type, entity and account type) | E23: 401(K) or Profit-Sharing Plan (including, solo 401(K) and retirement trusts) | I23: KPS
A24: Questionnaire | B24: =B23 -> CompanyAccountType | C24: =C23 -> ACCOUNT TYPE (Please check the row 54 for required documentation based on the selected legal type, entity and account type) | E24: Pooled Investment Fund (Hedge Fund, Private Equity Fund, Venture Capital Fund) | I24: PIF
A25: Questionnaire | B25: =B24 -> CompanyAccountType | C25: =C24 -> ACCOUNT TYPE (Please check the row 54 for required documentation based on the selected legal type, entity and account type) | E25: Regulated Entity | I25: RE
A26: Questionnaire | B26: =B25 -> CompanyAccountType | C26: =C25 -> ACCOUNT TYPE (Please check the row 54 for required documentation based on the selected legal type, entity and account type) | E26: Publicly Traded Company | I26: PTC
A27: Questionnaire | B27: =B26 -> CompanyAccountType | C27: =C26 -> ACCOUNT TYPE (Please check the row 54 for required documentation based on the selected legal type, entity and account type) | E27: Tax Exempt Organizations Non-Profit (NPOs) and Non-Governmental Organizations (NGOs) | I27: TEONP
A28: Questionnaire | B28: =B27 -> CompanyAccountType | C28: =C27 -> ACCOUNT TYPE (Please check the row 54 for required documentation based on the selected legal type, entity and account type) | E28: Money Services Business (“MSBs”) or Money Transmitters (“MSTs”) | I28: MSBMST
A29: Questionnaire | B29: =B28 -> CompanyAccountType | C29: =C28 -> ACCOUNT TYPE (Please check the row 54 for required documentation based on the selected legal type, entity and account type) | E29: Mining Companies/Node Operators/ Mining Hardware Companies | I29: MCNO
A30: Questionnaire | B30: =B29 -> CompanyAccountType | C30: =C29 -> ACCOUNT TYPE (Please check the row 54 for required documentation based on the selected legal type, entity and account type) | E30: Initial Coin Offerings (“ICO”) | I30: ICO
A31: Questionnaire | B31: =B30 -> CompanyAccountType | C31: =C30 -> ACCOUNT TYPE (Please check the row 54 for required documentation based on the selected legal type, entity and account type) | E31: Trust | I31: TRUST
A32: Questionnaire | B32: =B31 -> CompanyAccountType | C32: =C31 -> ACCOUNT TYPE (Please check the row 54 for required documentation based on the selected legal type, entity and account type) | E32: Government Entity | I32: GE
A33: Questionnaire
A34: Questionnaire | B34: ='Company Info, Intended Activity'!G26 -> CompanyBusinessModel | C34: ='Company Info, Intended Activity'!B26 -> BUSINESS MODEL (Drop down depends on the selected Account type) | D34: Professional Services Provider (e.g., Legal services, Accounting, etc…) | E34: Legal and accounting services | F34: 1 | G34: =IF('Company Info, Intended Activity'!$C$25=FieldValidation!D34,F34,"") | H34: =IF('Company Info, Intended Activity'!$C$25=FieldValidation!D34,E34,"") | I34: PSP-legal | J34: PSP | M34: 1 | N34: =VLOOKUP(M34,$G$34:$H$85,2,FALSE) -> #N/A
A35: Questionnaire | B35: =B34 -> CompanyBusinessModel | C35: =C34 -> BUSINESS MODEL (Drop down depends on the selected Account type) | D35: =D34 -> Professional Services Provider (e.g., Legal services, Accounting, etc…) | E35: Real estate | F35: 2 | G35: =IF('Company Info, Intended Activity'!$C$25=FieldValidation!D35,F35,"") | H35: =IF('Company Info, Intended Activity'!$C$25=FieldValidation!D35,E35,"") | I35: PSP-legal | J35: PSP | M35: 2 | N35: =VLOOKUP(M35,$G$34:$H$85,2,FALSE) -> #N/A
A36: Questionnaire | B36: =B35 -> CompanyBusinessModel | C36: =C35 -> BUSINESS MODEL (Drop down depends on the selected Account type) | D36: =D35 -> Professional Services Provider (e.g., Legal services, Accounting, etc…) | E36: Investment Brokerage | F36: 3 | G36: =IF('Company Info, Intended Activity'!$C$25=FieldValidation!D36,F36,"") | H36: =IF('Company Info, Intended Activity'!$C$25=FieldValidation!D36,E36,"") | I36: PSP | J36: PSP | M36: 3 | N36: =VLOOKUP(M36,$G$34:$H$85,2,FALSE) -> #N/A
A37: Questionnaire | B37: =B36 -> CompanyBusinessModel | C37: =C36 -> BUSINESS MODEL (Drop down depends on the selected Account type) | D37: =D36 -> Professional Services Provider (e.g., Legal services, Accounting, etc…) | E37: Asset management | F37: 4 | G37: =IF('Company Info, Intended Activity'!$C$25=FieldValidation!D37,F37,"") | H37: =IF('Company Info, Intended Activity'!$C$25=FieldValidation!D37,E37,"") | I37: PSP | J37: PSP | M37: 4 | N37: =VLOOKUP(M37,$G$34:$H$85,2,FALSE) -> #N/A
A38: Questionnaire | B38: =B37 -> CompanyBusinessModel | C38: =C37 -> BUSINESS MODEL (Drop down depends on the selected Account type) | D38: Other non-financial company | E38: Advertising & Market Research | F38: 1 | G38: =IF('Company Info, Intended Activity'!$C$25=FieldValidation!D38,F38,"") | H38: =IF('Company Info, Intended Activity'!$C$25=FieldValidation!D38,E38,"") | I38: OC | J38: OC | M38: 5 | N38: =VLOOKUP(M38,$G$34:$H$85,2,FALSE) -> #N/A
A39: Questionnaire | B39: =B38 -> CompanyBusinessModel | C39: =C38 -> BUSINESS MODEL (Drop down depends on the selected Account type) | D39: =D38 -> Other non-financial company | E39: Agriculture, Fishing, Hunting, Forestry and Related Activities | F39: 2 | G39: =IF('Company Info, Intended Activity'!$C$25=FieldValidation!D39,F39,"") | H39: =IF('Company Info, Intended Activity'!$C$25=FieldValidation!D39,E39,"") | I39: OC | J39: OC | M39: 6 | N39: =VLOOKUP(M39,$G$34:$H$85,2,FALSE) -> #N/A
A40: Questionnaire | B40: =B39 -> CompanyBusinessModel | C40: =C39 -> BUSINESS MODEL (Drop down depends on the selected Account type) | D40: =D39 -> Other non-financial company | E40: Computer Programming & Related Services | F40: 3 | G40: =IF('Company Info, Intended Activity'!$C$25=FieldValidation!D40,F40,"") | H40: =IF('Company Info, Intended Activity'!$C$25=FieldValidation!D40,E40,"") | I40: OC | J40: OC | M40: 7 | N40: =VLOOKUP(M40,$G$34:$H$85,2,FALSE) -> #N/A
A41: Questionnaire | B41: =B40 -> CompanyBusinessModel | C41: =C40 -> BUSINESS MODEL (Drop down depends on the selected Account type) | D41: =D40 -> Other non-financial company | E41: Construction | F41: 4 | G41: =IF('Company Info, Intended Activity'!$C$25=FieldValidation!D41,F41,"") | H41: =IF('Company Info, Intended Activity'!$C$25=FieldValidation!D41,E41,"") | I41: OC | J41: OC | M41: 8 | N41: =VLOOKUP(M41,$G$34:$H$85,2,FALSE) -> #N/A
A42: Questionnaire | B42: =B41 -> CompanyBusinessModel | C42: =C41 -> BUSINESS MODEL (Drop down depends on the selected Account type) | D42: =D41 -> Other non-financial company | E42: Education | F42: 5 | G42: =IF('Company Info, Intended Activity'!$C$25=FieldValidation!D42,F42,"") | H42: =IF('Company Info, Intended Activity'!$C$25=FieldValidation!D42,E42,"") | I42: OC | J42: OC | M42: 9 | N42: =VLOOKUP(M42,$G$34:$H$85,2,FALSE) -> #N/A
A43: Questionnaire | B43: =B42 -> CompanyBusinessModel | C43: =C42 -> BUSINESS MODEL (Drop down depends on the selected Account type) | D43: =D42 -> Other non-financial company | E43: Electricity, Gas & Water Supply | F43: 6 | G43: =IF('Company Info, Intended Activity'!$C$25=FieldValidation!D43,F43,"") | H43: =IF('Company Info, Intended Activity'!$C$25=FieldValidation!D43,E43,"") | I43: OC | J43: OC | M43: 10 | N43: =VLOOKUP(M43,$G$34:$H$85,2,FALSE) -> #N/A
A44: Questionnaire | B44: =B43 -> CompanyBusinessModel | C44: =C43 -> BUSINESS MODEL (Drop down depends on the selected Account type) | D44: =D43 -> Other non-financial company | E44: Equipment Rental | F44: 7 | G44: =IF('Company Info, Intended Activity'!$C$25=FieldValidation!D44,F44,"") | H44: =IF('Company Info, Intended Activity'!$C$25=FieldValidation!D44,E44,"") | I44: OC | J44: OC | M44: 11 | N44: =VLOOKUP(M44,$G$34:$H$85,2,FALSE) -> #N/A
...

Sheet Sanctions and AML Information
A2: Corporate Account Opening Questionnaire Additional Information
A4: Section | B4: Question/Request | C4: Answer | E4: Comment/Instructions | G4: FieldCode | I4: Comment for development
A5: Active in or offering service to particular industries | B5: Are you active in or offer services to any of the following industries? | E5: Please provide an answer for each particular industry.
B6: Gambling | G6: ActOrServGambling | I6: dropdown/mandatory
B7: Adult entertainment | G7: ActOrServAdult | I7: dropdown/mandatory
B8: Arms industry and commerce | G8: ActOrServArms | I8: dropdown/mandatory
B9: Bars/Night clubs | G9: ActOrServBarsNight | I9: dropdown/mandatory
B10: Commerce of arts, luxury items (cars, boats, planes) | G10: ActOrServArtsLux | I10: dropdown/mandatory
B11: Commerce of minerals, precious metals, stones and gems | G11: ActOrServMinMetals | I11: dropdown/mandatory
B12: Commerce and manufacturing of alcohol and tobacco | G12: ActOrServAlcTobacco | I12: dropdown/mandatory
B13: Cloud mining | G13: ActOrServCloudMin | I13: dropdown/mandatory
B14: Cannabis-related industry | G14: ActOrServCannabis | I14: dropdown/mandatory
A16: Offering services to residents of particular countries | B16: Do you offer services to residents of any of the following countries or regions? | E16: Please provide an answer for each particular country.
B17: Iran | G17: ServResIran | I17: dropdown/mandatory
B18: Syria | G18: ServResSyria | I18: dropdown/mandatory
B19: North Korea | G19: ServResNorthKorea | I19: dropdown/mandatory
B20: Sudan/South Sudan | G20: ServResSudanSouthSudan | I20: dropdown/mandatory
B21: Somalia | G21: ServResSomalia | I21: dropdown/mandatory
B22: Myanmar (Burma) | G22: SevResMaynmar | I22: dropdown/mandatory
B23: Cuba | G23: ServResCuba | I23: dropdown/mandatory
B24: Yemen | G24: ServResYemen | I24: dropdown/mandatory
B25: Zimbabwe | G25: ServResZimbabwe | I25: dropdown/mandatory
B26: Crimea region | G26: ServResCrimea | I26: dropdown/mandatory
A28: Money laundering or Terrorist financing | B28: Has the company or have its representatives ever been investigated, indicted, convicted or was in a civil enforcement action related to money laundering/terrorist financing or any other regulatory matter? | E28: If yes, please provide additional information. | G28: CompUBOLaundTerrYesNo | I28: dropdown/mandatory
B29: If yes, please provide additional information below:
G30: CompUBOLaundTerrDesc | I30: text box

Sheet Entity and Documents Def
A2: Business Logic to Select Relevant Documentation Type
C3: ='Company Info, Intended Activity'!B25 -> ACCOUNT TYPE (Please check the row 54 for required documentation based on the selected legal type, entity and account type) | D3: =IF(ISBLANK('Company Info, Intended Activity'!C25),"",VLOOKUP('Company Info, Intended Activity'!C25,FieldValidation!E19:I32,5,FALSE)) | H3: Please provide the following information for all individuals who directly or indirectly, through any contract, arrangement, understanding, relationship or otherwise, own 25% or more of the equity interests of the legal entity customer:
C4: ='Company Info, Intended Activity'!B26 -> BUSINESS MODEL (Drop down depends on the selected Account type) | D4: =IF(ISBLANK('Company Info, Intended Activity'!C26),"",VLOOKUP('Company Info, Intended Activity'!C26,FieldValidation!E34:J85,5,FALSE))
C5: Business model linked to | D5: =IF(ISBLANK('Company Info, Intended Activity'!C26),"",VLOOKUP('Company Info, Intended Activity'!C26,FieldValidation!E34:J85,6,FALSE)) | F5: =IF(OR(ISBLANK('Company Info, Intended Activity'!C26),ISBLANK('Company Info, Intended Activity'!C25))," ",IF(D5<>D3,H5," ")) | H5: Please make sure that Account Type and Business Model match!
C6: Relevant Document Guidance Class | D6: =D4
B7: =FieldValidation!E15 -> Trust | C7: Legal Form | D7: ='Company Info, Intended Activity'!C22 -> 0 | F7: =IF(UPPER(D7)=UPPER(B7),IF(D3<>UPPER(D7),"For legal entity Trust pls. choose account type Trust!",""),"")
C8: Relevant selection based Industry and Fin.Serv.Type and corrected for Publicly Traded or Regulated | D8: =IF(D7=B7,B7,D6) | H8: Please select Legal Form, Account Type and Business Model!
A11: Required Documents Guidance Legal Entity
A12: Required Documents Guidance Legal Entity | B12: Legal Entity Type | C12: Definition | D12: Required Documentation | E12: Owners or Trustees TITLE | F12: Owners or Trustees | G12: Representatives and Acc. Users TITLE | H12: Representatives and Acc Users | I12: Internal Guidance
A13: LLC | B13: LLC | C13: A limited liability company (LLC) is a business structure in the US whereby the owners are not personally liable for the company's debts or liabilities. While the limited liability feature is similar to that of a corporation, the availability of flow-through taxation to the members of an LLC is a feature of partnerships (and not an LLC). | D13: - Certificate of Incorporation or Operating Agreement - W-9 Form. - Any document disclosing the company's business address (e.g. bank account statement, utility bill or equivalent). | F13: - High resolution image of international passport or other government issued ID document of all individual owners with a company share of 25 % or higher. | H13: - High resolution image of international passport or other government issued ID document of individual with significant responsibility to control, manage, or direct a legal entity customer (e.g. CEO, COO, CFO, GP, VP, Treasurer...) if not already provided. - High resolution image of international passport or other government issued ID document of all authorized account operatives.
A14: S Corporation | B14: S Corporation | C14: An S corporation, also known as an S subchapter, refers to a type of corporation. Requirements give a corporation with 100 shareholders or less the benefit of incorporation while being taxed as a partnership. Corporate taxes filed under Subchapter S may pass business income, losses, deductions, and credits to shareholders. Shareholders report income and losses on individual tax returns, and pay taxes at ordinary tax rates. S corporation shareholders must be individuals, specific trusts and estates, or certain tax-exempt organizations. | D14: - Certificate of Incorporation or Memorandum and Articles of Association - W-9 Form. - Any document disclosing the company's business address (e.g. bank account statement, utility bill or eqiuvalent). | F14: - High resolution image of international passport or other government issued ID document of all individual owners with a company share of 25 % or higher. | H14: - High resolution image of international passport or other government issued ID document of individual with significant responsibility to control, manage, or direct a legal entity customer (e.g. CEO, COO, CFO, GP, VP, Treasurer...) if not already provided. - High resolution image of international passport or other government issued ID document of all authorized account operatives.
A15: Limited Partnership | B15: Limited Partnership | C15: A limited partnership exists when two or more partners go into business together, but one or more of the partners are only liable up to the amount of their investment. The general partner of the LP has unlimited liability. There are three types of partnerships: limited partnership, general partnership, and joint venture. Most U.S. states govern the formation of limited partnerships, requiring registration with the Secretary of State. | D15: - Certificate of Incorporation and Partnership Agreement. - W-9 Form. - Any document disclosing the company's business address (e.g. bank account statement, utility bill or equivalent). | F15: - High resolution image of international passport or other government issued ID document of all individual owners with a company share of 25 % or higher. | H15: - High resolution image of international passport or other government issued ID document of individual with significant responsibility to control, manage, or direct a legal entity customer (e.g. CEO, COO, CFO, GP, VP, Treasurer...) if not already provided. - High resolution image of international passport or other government issued ID document of all authorized account operatives.
A16: Trust | B16: Trust | C16: A trust is a fiduciary relationship in which one party, known as a trustor/settlor, gives another party, the trustee, the right to hold title to property or assets for the benefit of a third party, the beneficiary. Trusts are established to provide legal protection for the trustor’s assets, to make sure those assets are distributed according to the wishes of the trustor, and to save time, reduce paperwork and, in some cases, avoid or reduce inheritance or estate taxes. In finance, a trust can also be a type of closed-end fund built as a public limited company. | D16: - Trust deed. - W-9 Form. - Any document disclosing the company's business address (e.g. bank account statement, utility bill or equivalent). | F16: - High resolution image of international passport or other government issued ID document of at least one Trustee or equivalent individual with at least 25 % or more equity interest in the Trust. | H16: - High resolution image of international passport or other government issued ID document of all authorized account operatives.
A17: Government Entity | B17: Government Entity, Tax Exempt, Non-Profit and Non-Governmental Organizations | H17: - High resolution image of international passport or other government issued ID document of all authorized account operatives.
A18: Other | B18: Other | C18: Other entity types such as sole proprietorship, C-Corporation, LLP, LLLP, PLLC, PC and others. | D18: - Certificate of Incorporation or extract from the business registry. - W-9 Form. - Any document disclosing the company's business address (e.g. bank account statement, utility bill). | F18: - High resolution image of international passport or other government issued ID document of all individual owners with a company share of 25 % or higher. | H18: - High resolution image of international passport or other government issued ID document of individual with significant responsibility to control, manage, or direct a legal entity customer (e.g. CEO, COO, CFO, GP, VP, Treasurer...) if not already provided. - High resolution image of international passport or other government issued ID document of all authorized account operatives.
A21: Required Documents Guidance Class
A22: Required Documents Guidance Class | B22: Entity Type | C22: Definition | D22: Required Documentation | E22: Owners or Trustees TITLE | F22: Owners or Trustees | G22: Representatives and Acc. Users TITLE | H22: Representatives and Acc Users | I22: Internal Guidance
A23: PTC | B23: Publicly Traded Companies | C23: A publicly traded company is a company whose ownership is dispersed among the general public in many shares of stock which are freely traded on a stock exchange or in over the counter (“OTC”) markets. Because these companies are strictly regulated and have to comply with a number of stringent requirements prior to (and after) going public, this allows Bitstamp to take comfort in their risk status. | E23: This worksheet is not applicable for the selected entity type. | G23: Representatives and Account Users | I23: The prospective customer must be listed on a major stock exchange (i.e., NYSE, NASDAQ, Euronext, London Stock Exchange Group) and not have significant private ownership greater than 25%: a. Current screenshot from major exchange listing the company’s ticker symbol and performance (i.e., demonstrating active status) b. Screenshot from Financial Times (ft.com) evidencing the free float for the entity (thereby demonstrating that there is no significant ownership interest greater than 25%). i. Note: If there is significant private ownership greater than 25% the Analyst must treat the Company as an Operating Company.
A24: RE-insurance | B24: Regulated Entities | C24: Regulated entities are entities that are regulated by internationally-recognized regulatory authorizes and have undergone AML checks, which in turn allows Bitstamp to take comfort in their risk status. Regulated entities can be any one of the following entities types: registered broker-dealers, registered investment advisors, insurance firms, etc. Broker-dealers: With few exceptions, broker dealers must register with the Securities and Exchange Commission and be members of FINRA. Section 3(a)(4)(A) of the Securities Exchange Act of 1934 generally defines a “broker” broadly as any person engaged in the business of effecting transactions in securities for the account of others. Unlike a broker, who acts as agent, a “dealer acts as principal. Section 3(a)(5)(A) of the Act generally defines a “dealer” as any person engaged in the business of buying and selling securities for his own account through a broker or otherwise. Registered Investment Advisor: An investment advisor is defined by the Investment Advisors Act of 1940, as any person or group that makes investment recommendations or conducts securities analysis in return for a fee, whether through direct management of client assets or via written publications. Also referred toa as a financial advisor, an investment advisor who has sufficient assets to be registered with the Securities and Exchange Commission (SEC) is knowns as a Registered Investment Advisor, or RIA. Other regulators that may govern Bitstamp customers: CFTC, NFA, FINRA If the prospective customer has lost its regulated status or is regulated by a non-recognized regulator, the Customer must be treated as an Operating Company. | E24: This worksheet is not applicable for the selected entity type. | G24: Representatives and Account Users | I24: Proof of registration is required and this will eliminate the need to drill down to 25% beneficial ownership for the entity. AML Policy review is not required. If the prospective customer has lost its regulated status or is regulated by a non-recognized regulator, the Customer must be treated as an Operating Company.
A25: RE-broker | B25: Regulated Entities | C25: Regulated entities are entities that are regulated by internationally-recognized regulatory authorizes and have undergone AML checks, which in turn allows Bitstamp to take comfort in their risk status. Regulated entities can be any one of the following entities types: registered broker-dealers, registered investment advisors, insurance firms, etc. Broker-dealers: With few exceptions, broker dealers must register with the Securities and Exchange Commission and be members of FINRA. Section 3(a)(4)(A) of the Securities Exchange Act of 1934 generally defines a “broker” broadly as any person engaged in the business of effecting transactions in securities for the account of others. Unlike a broker, who acts as agent, a “dealer acts as principal. Section 3(a)(5)(A) of the Act generally defines a “dealer” as any person engaged in the business of buying and selling securities for his own account through a broker or otherwise. Registered Investment Advisor: An investment advisor is defined by the Investment Advisors Act of 1940, as any person or group that makes investment recommendations or conducts securities analysis in return for a fee, whether through direct management of client assets or via written publications. Also referred toa as a financial advisor, an investment advisor who has sufficient assets to be registered with the Securities and Exchange Commission (SEC) is knowns as a Registered Investment Advisor, or RIA. Other regulators that may govern Bitstamp customers: CFTC, NFA, FINRA If the prospective customer has lost its regulated status or is regulated by a non-recognized regulator, the Customer must be treated as an Operating Company. | D25: - Proof of registration as broker-dealer with FINRA. - AML Policy. | E25: Ownership Information | G25: Representatives and Account Users
A26: RE-advisor | B26: Regulated Entities | C26: Regulated entities are entities that are regulated by internationally-recognized regulatory authorizes and have undergone AML checks, which in turn allows Bitstamp to take comfort in their risk status. Regulated entities can be any one of the following entities types: registered broker-dealers, registered investment advisors, insurance firms, etc. Broker-dealers: With few exceptions, broker dealers must register with the Securities and Exchange Commission and be members of FINRA. Section 3(a)(4)(A) of the Securities Exchange Act of 1934 generally defines a “broker” broadly as any person engaged in the business of effecting transactions in securities for the account of others. Unlike a broker, who acts as agent, a “dealer acts as principal. Section 3(a)(5)(A) of the Act generally defines a “dealer” as any person engaged in the business of buying and selling securities for his own account through a broker or otherwise. Registered Investment Advisor: An investment advisor is defined by the Investment Advisors Act of 1940, as any person or group that makes investment recommendations or conducts securities analysis in return for a fee, whether through direct management of client assets or via written publications. Also referred to as a financial advisor, an investment advisor who has sufficient assets to be registered with the Securities and Exchange Commission (SEC) is knowns as a Registered Investment Advisor, or RIA. Other regulators that may govern Bitstamp customers: CFTC, NFA, FINRA If the prospective customer has lost its regulated status or is regulated by a non-recognized regulator, the Customer must be treated as an Operating Company. | D26: - Confirmation on Registration as an Investment Advisor. - AML Policy. | E26: Ownership Information | G26: Representatives and Account Users
A27: PSP | B27: Professional Services Provider (e.g., Legal services, Accounting, etc…) | C27: A professional service provider acts as an intermediary between its client and a financial institution. Professional service providers include lawyers, accountants, investment brokers, and other third parties that act as financial liaisons for their clients. These providers may conduct financial dealings for their clients. For example, an attorney may perform services for a client, or arrange for services to be performed on the client’s behalf, such as settlement of real estate transactions, asset transfers, management of client monies, investment services, and trust arrangements. | D27: - AML Policy. - Do you require any money transmitter licences in the states in which you operate? | E27: Ownership Information | G27: Representatives and Account Users
A28: PSP-legal | B28: Professional Services Provider (e.g., Legal services, Accounting, etc…) | C28: A professional service provider acts as an intermediary between its client and a financial institution. Professional service providers include lawyers, accountants, investment brokers, and other third parties that act as financial liaisons for their clients. These providers may conduct financial dealings for their clients. For example, an attorney may perform services for a client, or arrange for services to be performed on the client’s behalf, such as settlement of real estate transactions, asset transfers, management of client monies, investment services, and trust arrangements. | E28: Ownership Information | G28: Representatives and Account Users
A29: OC | B29: Other non-financial company | C29: An operating company is defined as accompany that makes a good or provides a service that it then sells to customers or clients. An operating company contrasts with a holding company, whose main function is to own other companies. | E29: Ownership Information | G29: Representatives and Account Users
A30: PIV | B30: Personal Investment Vehicle | C30: A personal investment vehicle is defined as a company whose sole purpose is to invest on behalf of the beneficial owner. A personal investment vehicle does not provide goods or services to customers or clients. In addition, a personal investment vehicle does not allow outside investors. | E30: Ownership Information | G30: Representatives and Account Users | I30: The following website may be helpful: https://www.bizfilings.com/state-guide
A31: PTF | B31: Proprietary Trading Firm | C31: A proprietary trading firm trades stocks, bonds, currencies, commodities, their derivatives, or other financial instruments with the firm’s own money. Proprietary traders use a variety of strategies such as arbitrage, fundamental analysis, and global macro trading. | E31: Ownership Information | G31: Representatives and Account Users
A32: GE | B32: Government Entity | C32: Any state or political subdivision of a state, including: any agency, authority, or instrumentality of the state or political subdivision; a plan or pool of assets controlled by the state or political subdivision or any agency, authority, or instrumentality thereof, acting in their official capacity, | D32: - Commission from the Government stating they are the elected official and the term they are elected for (if applicable). - Self-Attestation from the Authorized Signer stating they are authorized to act on behalf of the government entity they represent. | E32: This worksheet is not applicable for the selected entity type. | G32: Representatives and Account Users
A33: Trust | B33: Trust | C33: A trust is a fiduciary relationship in which one party, known as a settlor, gives another party, the trustee, the right to hold title to property or assets for the benefit of a third party, the beneficiary. | E33: Information on Settlor(s) Trustee(s) | G33: Representatives and Account Users
A34: KPS | B34: 401(K) or Profit-Sharing Plan (including, solo 401(K) and retirement trusts) | C34: A 401(K) plan is a qualified employer-established plan to which eligible employees may make salary deferral (salary reduction) contributions on a post-tax basis. Employers offering a 401(K) plan may make matching or non-elective contributions to the plan on behalf of eligible employees and may also add a profit-sharing feature to the plan. Earning in a 401(K) plan accrue on a tax deferred basis. A Profit-Sharing Plan, also known as a deferred profit-sharing plan or DSPS, is a plan that gives employees a share in the profits of a company. Under this type of plan, an employee receives a percentage of a company’s profits based on its quarterly or annual earnings. | D34: - IRA/401k Statement. | E34: Information on Plan Sponsor, Plan Administrator, Trustee | G34: Representatives and Account Users
A35: PIF | B35: Pooled Investment Fund (Hedge Fund, Private Equity Fund, Venture Capital Fund) | C35: 1. Hedge Funds: are alternative investments using pooled funds that employ numerous different strategies to earn active return, or alpha, for their investors. Hedge funds may be aggressively managed or make use of derivatives and leverage in both domestic and international markets with the goal of generating high returns (either in an absolute sense or over a specified market benchmark). It is important to note that hedge funds are generally only accessible to accredited investors as they require less SEC regulations than other funds. One aspect that has set the hedge fund industry apart is the fact that hedge funds face less regulation than mutual funds and other investment vehicles. 2. A private equity fund typically refers to a general partnership formed by PE firms, which are utilized to invest in private companies. Private equity funds may invest directly in equity securities of the target investment, in the form of mezzanine debt, or in both equity and debt. 3. Venture Capital funds are investment funds that manage the money of investors who seek private equity stakes in start-up and small to medium sized enterprises with strong growth potential. These investments are generally characterized as high-risk/high-return opportunities. In the past, venture capital investments were only accessible to professional venture capitalists although now accredited investors have a greater ability to take part in venture capital investments. | D35: - Private Placement Memorandum/Offering Memorandum/Offering Literature. - AML comfort letter from the fund administrator. - Do you already have any investors? Does any investor hold more than 25% of the total AUM? | E35: This worksheet is not applicable for the selected entity type. | G35: Representatives and Account Users | I35: 1. Private Placement Memorandum/Offering Memorandum/Offering Literature can be referenced a number of different ways. Explain to the client that you are looking for the legal document that states the objectives, risk, and terms of an investment involved with a private placement. This document includes items such as a company’s financial statements, management biographies, a detailed description of the business operations and more. 2. There will not always be a Fund Administrator. For example, Private Equity funds will not necessarily have a Fund Administrator, and often times will have the law firm they have hired conduct AML/KYC screening for potential investors as opposed to relying on an outside Fund Administrator to perform these services. Note: Beneficial ownership for a fund can change daily, rather than identify 25% level ownership, we will identify and vet the control persons and entities as described below.
A36: PIF-venture | B36: Pooled Investment Fund (Hedge Fund, Private Equity Fund, Venture Capital Fund) | C36: 1. Hedge Funds: are alternative investments using pooled funds that employ numerous different strategies to earn active return, or alpha, for their investors. Hedge funds may be aggressively managed or make use of derivatives and leverage in both domestic and international markets with the goal of generating high returns (either in an absolute sense or over a specified market benchmark). It is important to note that hedge funds are generally only accessible to accredited investors as they require less SEC regulations than other funds. One aspect that has set the hedge fund industry apart is the fact that hedge funds face less regulation than mutual funds and other investment vehicles. 2. A private equity fund typically refers to a general partnership formed by PE firms, which are utilized to invest in private companies. Private equity funds may invest directly in equity securities of the target investment, in the form of mezzanine debt, or in both equity and debt. 3. Venture Capital funds are investment funds that manage the money of investors who seek private equity stakes in start-up and small to medium sized enterprises with strong growth potential. These investments are generally characterized as high-risk/high-return opportunities. In the past, venture capital investments were only accessible to professional venture capitalists although now accredited investors have a greater ability to take part in venture capital investments. | E36: Ownership Information | G36: Representatives and Account Users
A37: TEONP | B37: Tax Exempt Organizations Non-Profit (NPOs) and Non-Governmental Organizations (NGOs) | C37: Tax exempt organization are defined pursuant to Title 26 section 501(a) of the United States Code, typically this is a corporation, trust unincorporated association or other type of organization that is exempt from federal tax. This includes all 501(c) non-profit organization, but most common are 501(c)(3), which range from charitable foundations to universities and churches. However, certain organization to support particular cryptocurrencies may be organized under 501(a) or the IRS code, wherein although similar to 501(c)(3) as charitable organization providing services to the public 501(a) organization are formed exclusively to promote the welfare of a certain group of people such as employees. Membership is limited to the group whom the organization represents. Primarily there are three fundamental classifications of tax-exempt entities: 1. A public charity, identified by the Internal Revenue Service as “not a private foundation”, normally receives a substantial part of its income, directly or indirectly, from the general public or from the government. The public support must be fairly broad, not limited to a few individuals or families. Public charities are defined in the Internal Revenue Code under sections 509(a)(1) through 509(a)(4). 2. A private foundation, sometimes called a non-operating foundation, receives most of its income from investments and endowment. This income is used to make grants to other organization, rather than being disbursed directly for charitable activities. Private foundations are defined in the Internal Revenue Code under section 509(a) as 501(c)(3) organization, which do not qualify as public charities. 3. Churches and religious organization must meet specific requirement in order to obtain and maintain tax exempt status; these are outlined in IRS Publication 1828: Tax guide for churches and religious organization, which outlines activities allowed and not allowed by churches and religious organization under the 501(c)(3) designation. | D37: - Internal Revenue Service Form 990. - List of significant donors (contributed more than 25% of the total donated funds). | E37: This worksheet is not applicable for the selected entity type. | G37: Representatives and Account Users | I37: Individuals with Significant Control are determined from a review of the Form 990 and factors to consider include title (officers or directors), salary, and hours worked per week.
A38: MSBMST | B38: Money Services Business (“MSBs”) or Money Transmitters (“MSTs” | C38: Money Services Businesses are non-bank financial institutions that provide certain financial services to their customers. They range in size and complexity, from small, one-shop businesses to multi-state sophisticated providers. As defined by FinCEN, MSBs include five distinct types of financial services providers (and the U.S. Postal Service): 1. Currency dealer or exchanger, 2. Check casher, 3. Issuer of traveller’s check, 4. Seller or redeemer of traveller’s checks, money orders or stored value, 5. Money Transmitter, 6. US Postal Service Note: There is a threshold requirement for businesses in the first four categories – a business that engages in such transactions will not be considered a MSB if it does not engage in such transactions in an amount greater than $1,000 for any person on any day in one or more transactions. The threshold applies separately to each activity, so if the threshold is not met for the specific activity, the business engaged in that activity is not a MSB on the basis of that activity. It should also be noted that MSBs do NOT include the following: 1. A bank. As that term is defined in 31 CFR 1010.100(d) (formerly 31 CFR 103.11(c)), or 2. A person registered with, and regulated or examined by, the SEC or the CFTC. MSBs serve important functions, including facilitating remittances and providing other financial services; however, their very nature makes them more at risk for being used to facilitate money laundering and financing of terrorist activities. As such, MSBs are required to establish and maintain effective written AML programs reasonably designed to prevent the MSB from being used to facilitate money laundering and terrorist financing. | D38: - BSA/AML Policy. - Please provide a full list of regulatory licenses and/or registrations under which your company currently operates. - Provide your current operating hot wallet address. | E38: Ownership Information | F38: - High quality scans of their proof of residency documents (e.g. bank account statements, utility bills). | G38: Representatives and Account Users
A39: MSBMST-ATM | B39: Money Services Business (“MSBs”) or Money Transmitters (“MSTs” | C39: Money Services Businesses are non-bank financial institutions that provide certain financial services to their customers. They range in size and complexity, from small, one-shop businesses to multi-state sophisticated providers. As defined by FinCEN, MSBs include five distinct types of financial services providers (and the U.S. Postal Service): 1. Currency dealer or exchanger, 2. Check casher, 3. Issuer of traveller’s check, 4. Seller or redeemer of traveller’s checks, money orders or stored value, 5. Money Transmitter, 6. US Postal Service Note: There is a threshold requirement for businesses in the first four categories – a business that engages in such transactions will not be considered a MSB if it does not engage in such transactions in an amount greater than $1,000 for any person on any day in one or more transactions. The threshold applies separately to each activity, so if the threshold is not met for the specific activity, the business engaged in that activity is not a MSB on the basis of that activity. It should also be noted that MSBs do NOT include the following: 1. A bank. As that term is defined in 31 CFR 1010.100(d) (formerly 31 CFR 103.11(c)), or 2. A person registered with, and regulated or examined by, the SEC or the CFTC. MSBs serve important functions, including facilitating remittances and providing other financial services; however, their very nature makes them more at risk for being used to facilitate money laundering and financing of terrorist activities. As such, MSBs are required to establish and maintain effective written AML programs reasonably designed to prevent the MSB from being used to facilitate money laundering and terrorist financing. | D39: - BSA/AML Policy. - Please provide a full list of regulatory licenses and/or registrations under which your company currently operates. - Locations of your ATMs. - Do you operate 1-way or 2-way ATMs? - Provide your current operating hot wallet address. | E39: Ownership Information | G39: Representatives and Account Users | H39: - High quality scans of proof of residency documents (e.g. bank account statements, utility bills) of all account operatives
